<?xml version="1.0"?>
<!-- created with Phobos 1.0.1 "Capricious Choutengan" -->
  <robot name="m2">
    
    <link name="world"/>
    
    <link name="chassis">
      <inertial>`
        <origin xyz="0 0 0" rpy="0 0 0"/>
        <mass value="0.01"/>
        <inertia ixx="0.001" ixy="0" ixz="0" iyy="0.001" iyz="0" izz="0.001"/>
      </inertial>
      <visual name="body_lights">
        <origin xyz="0.07415 0.00012 0.24822" rpy="0 0 0"/>
        <geometry>
          <mesh filename="package://m2_description/meshes/dae/body_lights.dae" scale="1.0 1.0 1.0"/>
        </geometry>
        <material name="01 - Default.001"/>
      </visual>
      <visual name="body_vis">
        <origin xyz="0.01142 0.00023 0.57838" rpy="0 0 0"/>
        <geometry>
          <mesh filename="package://m2_description/meshes/dae/Untitled.213.dae" scale="1.0 1.0 1.0"/>
        </geometry>
        <material name="01 - Default.001"/>
      </visual>
      <visual name="chassis_vis">
        <origin xyz="0 0 0" rpy="0 0 0"/>
        <geometry>
          <mesh filename="package://m2_description/meshes/dae/chassis_vis.dae" scale="1.0 1.0 1.0"/>
        </geometry>
        <material name="01 - Default.001"/>
      </visual>
      <visual name="vlp16_front_vis">
        <origin xyz="0.54676 0.00037 0.72861" rpy="1.5708 0.46426 0"/>
        <geometry>
          <mesh filename="package://m2_description/meshes/dae/vlp16_front_vis.dae" scale="1.0 1.0 1.0"/>
        </geometry>
        <material name="01 - Default.001"/>
      </visual>
      <visual name="vlp16_top_vis">
        <origin xyz="0.11051 0.0014 1.04234" rpy="-1.5708 0 0"/>
        <geometry>
          <mesh filename="package://m2_description/meshes/dae/vlp16_top_vis.dae" scale="1.0 1.0 1.0"/>
        </geometry>
        <material name="01 - Default.001"/>
      </visual>
      <visual name="vlp32c_vis">
        <origin xyz="0.11195 0.00142 1.30874" rpy="-1.5708 0 0"/>
        <geometry>
          <mesh filename="package://m2_description/meshes/dae/vlp32c_vis.dae" scale="1.0 1.0 1.0"/>
        </geometry>
        <material name="01 - Default.001"/>
      </visual>
      <collision name="body">
        <origin xyz="0.00514 0.00023 0.42524" rpy="0 0 0"/>
        <geometry>
          <box size="2.01448 0.94935 1.16925"/>
        </geometry>
      </collision>
      <collision name="chassis">
        <origin xyz="0.01121 0.00023 0.02431" rpy="0 0 0"/>
        <geometry>
          <box size="1.9958 0.72 0.35508"/>
        </geometry>
      </collision>
      <collision name="vlp16_front">
        <origin xyz="0.55851 0.00023 0.74921" rpy="3.14159 0.46426 0"/>
        <geometry>
          <cylinder radius="0.05164" length="0.07275"/>
        </geometry>
      </collision>
      <collision name="vlp16_top">
        <origin xyz="0.11195 0.00142 1.07434" rpy="0 0 0"/>
        <geometry>
          <cylinder radius="0.05164" length="0.08686"/>
        </geometry>
      </collision>
      <collision name="vlp32c">
        <origin xyz="0.11195 0.0019 1.25215" rpy="0 0 0"/>
        <geometry>
          <cylinder radius="0.06976" length="0.25"/>
        </geometry>
      </collision>
    </link>

    <link name="drive_motor_lb">
      <inertial>
        <origin xyz="0 0 0" rpy="0 0 0"/>
        <mass value="0.001"/>
        <inertia ixx="0.001" ixy="0" ixz="0" iyy="0.001" iyz="0" izz="0.001"/>
      </inertial>
      <visual name="drive_motor_lb_vis">
        <origin xyz="0 0 0" rpy="0 0 0"/>
        <geometry>
          <mesh filename="package://m2_description/meshes/dae/drive_motor_lb_vis.dae" scale="1.0 1.0 1.0"/>
        </geometry>
        <material name="01 - Default.001"/>
      </visual>
      <collision name="drive_motor_lb_vis">
        <origin xyz="0 0.09943 0.0535" rpy="0 0 0"/>
        <geometry>
          <box size="0.129 0.34444 0.107"/>
        </geometry>
      </collision>
    </link>

    <link name="drive_motor_lf">
      <inertial>
        <origin xyz="0 0 0" rpy="0 0 0"/>
        <mass value="0.001"/>
        <inertia ixx="0.001" ixy="0" ixz="0" iyy="0.001" iyz="0" izz="0.001"/>
      </inertial>
      <visual name="drive_motor_lf_vis">
        <origin xyz="0 0 0" rpy="0 0 0"/>
        <geometry>
          <mesh filename="package://m2_description/meshes/dae/drive_motor_lf_vis.dae" scale="1.0 1.0 1.0"/>
        </geometry>
        <material name="01 - Default.001"/>
      </visual>
      <collision name="drive_motor_lf">
        <origin xyz="0 0.08243 0.0535" rpy="0 0 0"/>
        <geometry>
          <box size="0.129 0.31044 0.107"/>
        </geometry>
      </collision>
    </link>

    <link name="drive_motor_rb">
      <inertial>
        <origin xyz="0 0 0" rpy="0 0 0"/>
        <mass value="0.001"/>
        <inertia ixx="0.001" ixy="0" ixz="0" iyy="0.001" iyz="0" izz="0.001"/>
      </inertial>
      <visual name="drive_motor_rb_vis">
        <origin xyz="0 0 0" rpy="0 0 0"/>
        <geometry>
          <mesh filename="package://m2_description/meshes/dae/drive_motor_rb_vis.dae" scale="1.0 1.0 1.0"/>
        </geometry>
        <material name="01 - Default.001"/>
      </visual>
      <collision name="drive_motor_rb">
        <origin xyz="0 -0.09943 0.0535" rpy="0 0 0"/>
        <geometry>
          <box size="0.129 0.34444 0.107"/>
        </geometry>
      </collision>
    </link>

    <link name="drive_motor_rf">
      <inertial>
        <origin xyz="0 0 0" rpy="0 0 0"/>
        <mass value="0.001"/>
        <inertia ixx="0.001" ixy="0" ixz="0" iyy="0.001" iyz="0" izz="0.001"/>
      </inertial>
      <visual name="drive_motor_rf_vis">
        <origin xyz="0 0 0" rpy="0 0 0"/>
        <geometry>
          <mesh filename="package://m2_description/meshes/dae/drive_motor_rf_vis.dae" scale="1.0 1.0 1.0"/>
        </geometry>
        <material name="01 - Default.001"/>
      </visual>
      <collision name="drive_motor_rf">
        <origin xyz="0 -0.08243 0.0535" rpy="0 0 0"/>
        <geometry>
          <box size="0.129 0.31044 0.107"/>
        </geometry>
      </collision>
    </link>

    <link name="shock_lb_1">
      <inertial>
        <origin xyz="0 0 0" rpy="0 0 0"/>
        <mass value="0.001"/>
        <inertia ixx="0.001" ixy="0" ixz="0" iyy="0.001" iyz="0" izz="0.001"/>
      </inertial>
      <visual name="shock_lb_1_vis">
        <origin xyz="0 0 0" rpy="0.37525 -1.5708 0"/>
        <geometry>
          <mesh filename="package://m2_description/meshes/dae/shock_lb_1_vis.dae" scale="1.0 1.0 1.0"/>
        </geometry>
        <material name="01 - Default.001"/>
      </visual>
      <collision name="shock_lb_1">
        <origin xyz="0.0564 0.02221 0" rpy="0.37525 -1.5708 0"/>
        <geometry>
          <cylinder radius="0.026" length="0.143"/>
        </geometry>
      </collision>
    </link>

    <link name="shock_lb_2">
      <inertial>
        <origin xyz="0 0 0" rpy="0 0 0"/>
        <mass value="0.001"/>
        <inertia ixx="0.001" ixy="0" ixz="0" iyy="0.001" iyz="0" izz="0.001"/>
      </inertial>
      <visual name="shock_lb_2_vis">
        <origin xyz="0 0 0" rpy="0.37525 -1.5708 0"/>
        <geometry>
          <mesh filename="package://m2_description/meshes/dae/shock_lb_2_vis.dae" scale="1.0 1.0 1.0"/>
        </geometry>
        <material name="01 - Default.001"/>
      </visual>
      <collision name="shock_lb_2">
        <origin xyz="-0.01732 -0.00682 0" rpy="0.37525 -1.5708 0"/>
        <geometry>
          <cylinder radius="0.025" length="0.0588"/>
        </geometry>
      </collision>
    </link>

    <link name="shock_lf_1">
      <inertial>
        <origin xyz="0 0 0" rpy="0 0 0"/>
        <mass value="0.001"/>
        <inertia ixx="0.001" ixy="0" ixz="0" iyy="0.001" iyz="0" izz="0.001"/>
      </inertial>
      <visual name="shock_lf_1_vis">
        <origin xyz="0 0 0" rpy="0.37525 -1.5708 0"/>
        <geometry>
          <mesh filename="package://m2_description/meshes/dae/shock_lf_1_vis.dae" scale="1.0 1.0 1.0"/>
        </geometry>
        <material name="01 - Default.001"/>
      </visual>
      <collision name="shock_lf_1">
        <origin xyz="0.0564 0.02221 0" rpy="0.37525 -1.5708 0"/>
        <geometry>
          <cylinder radius="0.026" length="0.143"/>
        </geometry>
      </collision>
    </link>

    <link name="shock_lf_2">
      <inertial>
        <origin xyz="0 0 0" rpy="0 0 0"/>
        <mass value="0.001"/>
        <inertia ixx="0.001" ixy="0" ixz="0" iyy="0.001" iyz="0" izz="0.001"/>
      </inertial>
      <visual name="shock_lf_2_vis">
        <origin xyz="0 0 0" rpy="0.37525 -1.5708 0"/>
        <geometry>
          <mesh filename="package://m2_description/meshes/dae/shock_lf_2_vis.dae" scale="1.0 1.0 1.0"/>
        </geometry>
        <material name="01 - Default.001"/>
      </visual>
      <collision name="shock_lf_2">
        <origin xyz="-0.01732 -0.00682 0" rpy="0.37525 -1.5708 0"/>
        <geometry>
          <cylinder radius="0.025" length="0.0588"/>
        </geometry>
      </collision>
    </link>

    <link name="shock_rb_1">
      <inertial>
        <origin xyz="0 0 0" rpy="0 0 0"/>
        <mass value="0.001"/>
        <inertia ixx="0.001" ixy="0" ixz="0" iyy="0.001" iyz="0" izz="0.001"/>
      </inertial>
      <visual name="shock_rb_1_vis">
        <origin xyz="0 0 0" rpy="-0.37525 -1.5708 0"/>
        <geometry>
          <mesh filename="package://m2_description/meshes/dae/shock_rb_1_vis.dae" scale="1.0 1.0 1.0"/>
        </geometry>
        <material name="01 - Default.001"/>
      </visual>
      <collision name="shock_rb_1">
        <origin xyz="0.0564 -0.02221 0" rpy="-0.37525 -1.5708 0"/>
        <geometry>
          <cylinder radius="0.026" length="0.143"/>
        </geometry>
      </collision>
    </link>

    <link name="shock_rb_2">
      <inertial>
        <origin xyz="0 0 0" rpy="0 0 0"/>
        <mass value="0.001"/>
        <inertia ixx="0.001" ixy="0" ixz="0" iyy="0.001" iyz="0" izz="0.001"/>
      </inertial>
      <visual name="shock_rb_2_vis">
        <origin xyz="0 0 0" rpy="-0.37525 -1.5708 0"/>
        <geometry>
          <mesh filename="package://m2_description/meshes/dae/shock_rb_2_vis.dae" scale="1.0 1.0 1.0"/>
        </geometry>
        <material name="01 - Default.001"/>
      </visual>
      <collision name="shock_rb_2">
        <origin xyz="-0.01732 0.00682 0" rpy="-0.37525 -1.5708 0"/>
        <geometry>
          <cylinder radius="0.025" length="0.0588"/>
        </geometry>
      </collision>
    </link>

    <link name="shock_rf_1">
      <inertial>
        <origin xyz="0 0 0" rpy="0 0 0"/>
        <mass value="0.001"/>
        <inertia ixx="0.001" ixy="0" ixz="0" iyy="0.001" iyz="0" izz="0.001"/>
      </inertial>
      <visual name="shock_rf_1_vis">
        <origin xyz="0 0 0" rpy="-0.37525 -1.5708 0"/>
        <geometry>
          <mesh filename="package://m2_description/meshes/dae/shock_rf_1_vis.dae" scale="1.0 1.0 1.0"/>
        </geometry>
        <material name="01 - Default.001"/>
      </visual>
      <collision name="shock_rf_1">
        <origin xyz="0.0564 -0.02221 0" rpy="-0.37525 -1.5708 0"/>
        <geometry>
          <cylinder radius="0.026" length="0.143"/>
        </geometry>
      </collision>
    </link>

    <link name="shock_rf_2">
      <inertial>
        <origin xyz="0 0 0" rpy="0 0 0"/>
        <mass value="0.001"/>
        <inertia ixx="0.001" ixy="0" ixz="0" iyy="0.001" iyz="0" izz="0.001"/>
      </inertial>
      <visual name="shock_rf_2_vis">
        <origin xyz="0 0 0" rpy="-0.37525 -1.5708 0"/>
        <geometry>
          <mesh filename="package://m2_description/meshes/dae/shock_rf_2_vis.dae" scale="1.0 1.0 1.0"/>
        </geometry>
        <material name="01 - Default.001"/>
      </visual>
      <collision name="shock_rf_2">
        <origin xyz="-0.01732 0.00682 0" rpy="-0.37525 -1.5708 0"/>
        <geometry>
          <cylinder radius="0.025" length="0.0855"/>
        </geometry>
      </collision>
    </link>

    <link name="steering_strut_lb">
      <inertial>
        <origin xyz="0 0 0" rpy="0 0 0"/>
        <mass value="0.001"/>
        <inertia ixx="0.001" ixy="0" ixz="0" iyy="0.001" iyz="0" izz="0.001"/>
      </inertial>
      <visual name="steering_strut_lb_vis">
        <origin xyz="0 0 0" rpy="0 -1.5708 0"/>
        <geometry>
          <mesh filename="package://m2_description/meshes/dae/steering_strut_lb_vis.dae" scale="1.0 1.0 1.0"/>
        </geometry>
        <material name="01 - Default.001"/>
      </visual>
      <collision name="steering_strut_lb_vis">
        <origin xyz="-0.13494 0.19601 0" rpy="0 -1.5708 0"/>
        <geometry>
          <box size="0.129 0.43202 0.30988"/>
        </geometry>
      </collision>
    </link>

    <link name="steering_strut_lf">
      <inertial>
        <origin xyz="0 0 0" rpy="0 0 0"/>
        <mass value="0.001"/>
        <inertia ixx="0.001" ixy="0" ixz="0" iyy="0.001" iyz="0" izz="0.001"/>
      </inertial>
      <visual name="steering_strut_lf_vis">
        <origin xyz="0 0 0" rpy="0 -1.5708 0"/>
        <geometry>
          <mesh filename="package://m2_description/meshes/dae/steering_strut_lf_vis.dae" scale="1.0 1.0 1.0"/>
        </geometry>
        <material name="01 - Default.001"/>
      </visual>
      <collision name="steering_strut_lf">
        <origin xyz="-0.13494 0.19601 0" rpy="0 -1.5708 0"/>
        <geometry>
          <box size="0.129 0.43202 0.30988"/>
        </geometry>
      </collision>
    </link>

    <link name="steering_strut_rb">
      <inertial>
        <origin xyz="0 0 0" rpy="0 0 0"/>
        <mass value="0.001"/>
        <inertia ixx="0.001" ixy="0" ixz="0" iyy="0.001" iyz="0" izz="0.001"/>
      </inertial>
      <visual name="steering_strut_rb_vis">
        <origin xyz="0 0 0" rpy="0 -1.5708 0"/>
        <geometry>
          <mesh filename="package://m2_description/meshes/dae/steering_strut_rb_vis.dae" scale="1.0 1.0 1.0"/>
        </geometry>
        <material name="01 - Default.001"/>
      </visual>
      <collision name="steering_strut_rb">
        <origin xyz="-0.13494 -0.19601 0" rpy="0 -1.5708 0"/>
        <geometry>
          <box size="0.129 0.43202 0.30988"/>
        </geometry>
      </collision>
    </link>

    <link name="steering_strut_rf">
      <inertial>
        <origin xyz="0 0 0" rpy="0 0 0"/>
        <mass value="0.001"/>
        <inertia ixx="0.001" ixy="0" ixz="0" iyy="0.001" iyz="0" izz="0.001"/>
      </inertial>
      <visual name="steering_strut_rf_vis">
        <origin xyz="0 0 0" rpy="0 -1.5708 0"/>
        <geometry>
          <mesh filename="package://m2_description/meshes/dae/steering_strut_rf_vis.dae" scale="1.0 1.0 1.0"/>
        </geometry>
        <material name="01 - Default.001"/>
      </visual>
      <collision name="steering_strut_rf">
        <origin xyz="-0.13494 -0.19601 0" rpy="0 -1.5708 0"/>
        <geometry>
          <box size="0.129 0.43202 0.30988"/>
        </geometry>
      </collision>
    </link>

    <link name="wheel_lb">
      <inertial>
        <origin xyz="0 0 0" rpy="0 0 0"/>
        <mass value="0.001"/>
        <inertia ixx="0.001" ixy="0" ixz="0" iyy="0.001" iyz="0" izz="0.001"/>
      </inertial>
      <visual name="wheel_lb_vis">
        <origin xyz="3e-05 0.00876 0" rpy="0 0 0"/>
        <geometry>
          <mesh filename="package://m2_description/meshes/dae/wheel_lb_vis.dae" scale="1.0 1.0 1.0"/>
        </geometry>
        <material name="01 - Default.001"/>
      </visual>
      <collision name="wheel_lb">
        <origin xyz="0 0 0" rpy="1.5708 0 0"/>
        <geometry>
          <cylinder radius="0.22423" length="0.20878"/>
        </geometry>
      </collision>
    </link>

    <link name="wheel_lf">
      <inertial>
        <origin xyz="0 0 0" rpy="0 0 0"/>
        <mass value="0.001"/>
        <inertia ixx="0.001" ixy="0" ixz="0" iyy="0.001" iyz="0" izz="0.001"/>
      </inertial>
      <visual name="wheel_lf_vis">
        <origin xyz="0 0 0" rpy="0 0 0"/>
        <geometry>
          <mesh filename="package://m2_description/meshes/dae/wheel_lf_vis.dae" scale="1.0 1.0 1.0"/>
        </geometry>
        <material name="01 - Default.001"/>
      </visual>
      <collision name="wheel_lf">
        <origin xyz="3e-05 -0.00814 0" rpy="1.5708 0 0"/>
        <geometry>
          <cylinder radius="0.22423" length="0.20878"/>
        </geometry>
      </collision>
    </link>

    <link name="wheel_rb">
      <inertial>
        <origin xyz="0 0 0" rpy="0 0 0"/>
        <mass value="0.001"/>
        <inertia ixx="0.001" ixy="0" ixz="0" iyy="0.001" iyz="0" izz="0.001"/>
      </inertial>
      <visual name="wheel_rb_vis">
        <origin xyz="3e-05 -0.00876 0" rpy="0 0 0"/>
        <geometry>
          <mesh filename="package://m2_description/meshes/dae/wheel_rb_vis.dae" scale="1.0 1.0 1.0"/>
        </geometry>
        <material name="01 - Default.001"/>
      </visual>
      <collision name="wheel_rb">
        <origin xyz="0 0 0" rpy="1.5708 0 0"/>
        <geometry>
          <cylinder radius="0.22423" length="0.20878"/>
        </geometry>
      </collision>
    </link>

    <link name="wheel_rf">
      <inertial>
        <origin xyz="0 0 0" rpy="0 0 0"/>
        <mass value="0.001"/>
        <inertia ixx="0.001" ixy="0" ixz="0" iyy="0.001" iyz="0" izz="0.001"/>
      </inertial>
      <visual name="wheel_rf_vis">
        <origin xyz="-3e-05 -0.00814 0" rpy="0 0 0"/>
        <geometry>
          <mesh filename="package://m2_description/meshes/dae/wheel_rf_vis.dae" scale="1.0 1.0 1.0"/>
        </geometry>
        <material name="01 - Default.001"/>
      </visual>
      <collision name="wheel_rf">
        <origin xyz="0 0 0" rpy="1.5708 0 0"/>
        <geometry>
          <cylinder radius="0.22423" length="0.20878"/>
        </geometry>
      </collision>
    </link>

    <joint name="drive_motor_lb" type="revolute">
      <origin xyz="-0.07688 0.338 0" rpy="0 -1.5708 0"/>
      <parent link="steering_strut_lb"/>
      <child link="drive_motor_lb"/>
      <axis xyz="0 0 1.0"/>
      <limit lower="-3.141" upper="3.141" effort="0" velocity="0"/>
    </joint>

    <joint name="drive_motor_lf" type="revolute">
      <origin xyz="-0.07688 0.338 0" rpy="0 -1.5708 0"/>
      <parent link="steering_strut_lf"/>
      <child link="drive_motor_lf"/>
      <axis xyz="0 0 1.0"/>
      <limit lower="-3.141" upper="3.141" effort="0" velocity="0"/>
    </joint>

    <joint name="drive_motor_rb" type="revolute">
      <origin xyz="-0.07688 -0.338 0" rpy="0 -1.5708 0"/>
      <parent link="steering_strut_rb"/>
      <child link="drive_motor_rb"/>
      <axis xyz="0 0 1.0"/>
      <limit lower="-3.141" upper="3.141" effort="0" velocity="0"/>
    </joint>

    <joint name="drive_motor_rf" type="revolute">
      <origin xyz="-0.07688 -0.338 0" rpy="0 -1.5708 0"/>
      <parent link="steering_strut_rf"/>
      <child link="drive_motor_rf"/>
      <axis xyz="0 0 1.0"/>
      <limit lower="-3.141" upper="3.141" effort="0" velocity="0"/>
    </joint>

    <joint name="shock_lb_1" type="continuous">
      <origin xyz="-0.8202 0.10995 0.03063" rpy="0 1.5708 0"/>
      <parent link="chassis"/>
      <child link="shock_lb_1"/>
      <axis xyz="0 0 1.0"/>
      <limit effort="0" velocity="0"/>
    </joint>

    <joint name="shock_lb_2" type="continuous">
      <origin xyz="-0.02 0.114 -0.00044" rpy="0 0 0"/>
      <parent link="steering_strut_lb"/>
      <child link="shock_lb_2"/>
      <axis xyz="0 0 1.0"/>
      <limit effort="0" velocity="0"/>
    </joint>

    <joint name="shock_lf_1" type="continuous">
      <origin xyz="0.84304 0.10995 0.03063" rpy="0 1.5708 0"/>
      <parent link="chassis"/>
      <child link="shock_lf_1"/>
      <axis xyz="0 0 1.0"/>
      <limit effort="0" velocity="0"/>
    </joint>

    <joint name="shock_lf_2" type="continuous">
      <origin xyz="-0.02 0.114 0.00043" rpy="0 0 0"/>
      <parent link="steering_strut_lf"/>
      <child link="shock_lf_2"/>
      <axis xyz="0 0 1.0"/>
      <limit effort="0" velocity="0"/>
    </joint>

    <joint name="shock_rb_1" type="continuous">
      <origin xyz="-0.8202 -0.1095 0.03063" rpy="0 1.5708 0"/>
      <parent link="chassis"/>
      <child link="shock_rb_1"/>
      <axis xyz="0 0 1.0"/>
      <limit effort="0" velocity="0"/>
    </joint>

    <joint name="shock_rb_2" type="continuous">
      <origin xyz="-0.02 -0.114 -0.00044" rpy="0 0 0"/>
      <parent link="steering_strut_rb"/>
      <child link="shock_rb_2"/>
      <axis xyz="0 0 1.0"/>
      <limit effort="0" velocity="0"/>
    </joint>

    <joint name="shock_rf_1" type="continuous">
      <origin xyz="0.84304 -0.1095 0.03063" rpy="0 1.5708 0"/>
      <parent link="chassis"/>
      <child link="shock_rf_1"/>
      <axis xyz="0 0 1.0"/>
      <limit effort="0" velocity="0"/>
    </joint>

    <joint name="shock_rf_2" type="continuous">
      <origin xyz="-0.02 -0.114 0.00044" rpy="0 0 0"/>
      <parent link="steering_strut_rf"/>
      <child link="shock_rf_2"/>
      <axis xyz="0 0 1.0"/>
      <limit effort="0" velocity="0"/>
    </joint>

    <joint name="steering_strut_lb" type="continuous">
      <origin xyz="-0.81976 0.05092 -0.12893" rpy="0 1.5708 0"/>
      <parent link="chassis"/>
      <child link="steering_strut_lb"/>
      <axis xyz="0 0 1.0"/>
      <limit effort="0" velocity="0"/>
    </joint>

    <joint name="steering_strut_lf" type="continuous">
      <origin xyz="0.8426 0.05092 -0.12893" rpy="0 1.5708 0"/>
      <parent link="chassis"/>
      <child link="steering_strut_lf"/>
      <axis xyz="0 0 1.0"/>
      <limit effort="0" velocity="0"/>
    </joint>

    <joint name="steering_strut_rb" type="continuous">
      <origin xyz="-0.81976 -0.05047 -0.12893" rpy="0 1.5708 0"/>
      <parent link="chassis"/>
      <child link="steering_strut_rb"/>
      <axis xyz="0 0 1.0"/>
      <limit effort="0" velocity="0"/>
    </joint>

    <joint name="steering_strut_rf" type="continuous">
      <origin xyz="0.8426 -0.05047 -0.12893" rpy="0 1.5708 0"/>
      <parent link="chassis"/>
      <child link="steering_strut_rf"/>
      <axis xyz="0 0 1.0"/>
      <limit effort="0" velocity="0"/>
    </joint>

    <joint name="wheel_lb" type="continuous">
      <origin xyz="0 0.22997 0.0559" rpy="0 0 0"/>
      <parent link="drive_motor_lb"/>
      <child link="wheel_lb"/>
      <axis xyz="0 -1.0 0"/>
      <limit effort="0" velocity="0"/>
    </joint>

    <joint name="wheel_lf" type="continuous">
      <origin xyz="-3e-05 0.23811 0.0559" rpy="0 0 0"/>
      <parent link="drive_motor_lf"/>
      <child link="wheel_lf"/>
      <axis xyz="0 -1.0 0"/>
      <limit effort="0" velocity="0"/>
    </joint>

    <joint name="wheel_rb" type="continuous">
      <origin xyz="0 -0.22997 0.0559" rpy="0 0 0"/>
      <parent link="drive_motor_rb"/>
      <child link="wheel_rb"/>
      <axis xyz="0 -1.0 0"/>
      <limit effort="0" velocity="0"/>
    </joint>

    <joint name="wheel_rf" type="continuous">
      <origin xyz="0 -0.22997 0.0559" rpy="0 0 0"/>
      <parent link="drive_motor_rf"/>
      <child link="wheel_rf"/>
      <axis xyz="0 -1.0 0"/>
      <limit effort="0" velocity="0"/>
    </joint>

    <joint name="world" type="floating">
      <origin xyz="0 0 0" rpy="0 0 0"/>
      <parent link="world"/>
      <child link="chassis"/>
    </joint>

    <transmission name="wheel_rf">
      <type>transmission_interface/SimpleTransmission</type>
        <joint name="wheel_rf">
          <hardwareInterface>hardware_interface/EffortJointInterface</hardwareInterface>
        </joint>
        <actuator name="wheel_rf">
          <mechanicalReduction>1</mechanicalReduction>
          <hardwareInterface>hardware_interface/EffortJointInterface</hardwareInterface>
        </actuator>
    </transmission>

    <transmission name="wheel_lf">
      <type>transmission_interface/SimpleTransmission</type>
        <joint name="wheel_lf">
          <hardwareInterface>hardware_interface/EffortJointInterface</hardwareInterface>
        </joint>
        <actuator name="wheel_lf">
          <mechanicalReduction>1</mechanicalReduction>
          <hardwareInterface>hardware_interface/EffortJointInterface</hardwareInterface>
        </actuator>
    </transmission>

    <transmission name="wheel_rb">
      <type>transmission_interface/SimpleTransmission</type>
        <joint name="wheel_rb">
          <hardwareInterface>hardware_interface/EffortJointInterface</hardwareInterface>
        </joint>
        <actuator name="wheel_rb">
          <mechanicalReduction>1</mechanicalReduction>
          <hardwareInterface>hardware_interface/EffortJointInterface</hardwareInterface>
        </actuator>
    </transmission>

    <transmission name="wheel_lb">
      <type>transmission_interface/SimpleTransmission</type>
        <joint name="wheel_lb">
          <hardwareInterface>hardware_interface/EffortJointInterface</hardwareInterface>
        </joint>
        <actuator name="wheel_lb">
          <mechanicalReduction>1</mechanicalReduction>
          <hardwareInterface>hardware_interface/EffortJointInterface</hardwareInterface>
        </actuator>
    </transmission>

    <transmission name="steering_rf">
      <type>transmission_interface/SimpleTransmission</type>
        <joint name="steering_rf">
          <hardwareInterface>hardware_interface/EffortJointInterface</hardwareInterface>
        </joint>
        <actuator name="steering_rf">
          <mechanicalReduction>1</mechanicalReduction>
          <hardwareInterface>hardware_interface/EffortJointInterface</hardwareInterface>
        </actuator>
    </transmission>

    <transmission name="steering_lf">
      <type>transmission_interface/SimpleTransmission</type>
        <joint name="steering_lf">
          <hardwareInterface>hardware_interface/EffortJointInterface</hardwareInterface>
        </joint>
        <actuator name="steering_lf">
          <mechanicalReduction>1</mechanicalReduction>
          <hardwareInterface>hardware_interface/EffortJointInterface</hardwareInterface>
        </actuator>
    </transmission>

    <transmission name="steering_rb">
      <type>transmission_interface/SimpleTransmission</type>
        <joint name="steering_rb">
          <hardwareInterface>hardware_interface/EffortJointInterface</hardwareInterface>
        </joint>
        <actuator name="steering_rb">
          <mechanicalReduction>1</mechanicalReduction>
          <hardwareInterface>hardware_interface/EffortJointInterface</hardwareInterface>
        </actuator>
    </transmission>

    <transmission name="steering_lb">
      <type>transmission_interface/SimpleTransmission</type>
        <joint name="steering_lb">
          <hardwareInterface>hardware_interface/EffortJointInterface</hardwareInterface>
        </joint>
        <actuator name="steering_lb">
          <mechanicalReduction>1</mechanicalReduction>
          <hardwareInterface>hardware_interface/EffortJointInterface</hardwareInterface>
        </actuator>
    </transmission>

    <gazebo>
      
      <joint name="shock_lf" type="prismatic">
        <child>shock_lf_1</child>
        <parent>shock_lf_2</parent>
        <axis>
          <xyz>0 0 1</xyz>
          <limit>
            <lower>-0.025</lower>
            <upper>0.025</upper>
          </limit>
        </axis>
      </joint>

      <joint name="shock_lb" type="prismatic">
        <child>shock_lb_1</child>
        <parent>shock_lb_2</parent>
        <axis>
          <xyz>0 0 1</xyz>
          <limit>
            <lower>-0.025</lower>
            <upper>0.025</upper>
          </limit>
        </axis>
      </joint>

      <joint name="shock_rf" type="prismatic">
        <child>shock_rf_1</child>
        <parent>shock_rf_2</parent>
        <axis>
          <xyz>0 0 1</xyz>
          <limit>
            <lower>-0.025</lower>
            <upper>0.025</upper>
          </limit>
        </axis>
      </joint>

      <joint name="shock_rb" type="prismatic">
        <child>shock_rb_1</child>
        <parent>shock_rb_2</parent>
        <axis>
          <xyz>0 0 1</xyz>
          <limit>
            <lower>-0.025</lower>
            <upper>0.025</upper>
          </limit>
        </axis>
      </joint>

      <plugin name="gazebo_ros_control" filename="libgazebo_ros_control.so">
        <robotNamespace>m2</robotNamespace>
      </plugin>

    </gazebo>

  </robot>
